Workbook

Sheet Cover
B2: LEED v5 for Building Design and Construction: Core and Shell Scorecard
C3: BD+C CS credit category view | F3: Provides an overview of points per credit category
C4: BD+C CS impact area view | F4: Provides a directional indicator of the credits per impact area.
C5: Analytics | F5: Provides basic analytics derived from points, credit, and prerequisite data entered.
C7: How to use
C8: 1. Navigate to the "BD+C CS Credit Category View" tab
C9: 2. For each credit, enter the number of expected points in Columns A-C, titled "Yes", "Maybe" and "No".
D10: "Yes": Points will count towards your total.
D11: "Maybe": Points will count towards your totals.
D12: "No": Points will not count towards your totals.
C13: 3. For each prerequisite, utilize the checkbox in Columns A-C, titled "Yes", "Maybe" and "No". Please note prerequisites do not count toward point totals.
C14: 4. For Project Priorities, utilize column H to enter up to 9 credit names and anticipated points per credit.
C15: 5. "BD+C CS impact area view " tab will automatically update with all the decisions you made on the "BD+C CS Credit Category View" tab; no additional input is needed.
C16: * Feel free to customize this tool in any way that best suits your needs. Whether you need to add new columns or simply rearrange the layout to better fit your workflow, this tool is designed with flexibility in mind.

Sheet BD+C credit category view
L1: Total
A2: LEED v5 for Building Design and Construction: Core and Shell | L2: Yes | M2: =A84 -> 0 | N2: points | P2: Key:
A3: Project scorecard | L3: Maybe | M3: =B84 -> 0 | N3: points | P3: Prerequisite
L4: No | M4: =C84 -> 0 | N4: points | P4: Credit
I6: Total Possible Points | J6: Total Anticipated Points | L6: Total Anticipated Points | M6: =J84 -> 0 | N6: points
L7: Total Possible Points | M7: =I84 -> 110 | N7: points
A8: Yes | B8: Maybe | C8: No | L8: Responsible Party | M8: Notes
E9: Integrative Process, Planning and Assessments (IP) | I9: =SUM(I14:I15) -> 7 | J9: =SUM(J14:J15) -> 0
A10: FALSE | B10: FALSE | C10: FALSE | E10: IPp1 | F10: Climate Resilience Assessment | I10: Required
A11: FALSE | B11: FALSE | C11: FALSE | E11: IPp2 | F11: Human Impact Assessment | I11: Required | J11: Required
A12: FALSE | B12: FALSE | C12: FALSE | E12: IPp3 | F12: Carbon Assessment | I12: Required | J12: Required
A13: FALSE | B13: FALSE | C13: FALSE | E13: IPp4 | F13: Tenant Guidelines | I13: Required | J13: Required
A14: 0 | B14: 0 | C14: 0 | E14: IPc1 | F14: Integrative Design Process | I14: 1 | J14: =SUM(A14:B14) -> 0 | K14: =IF(J14>I14,"⚠","")
A15: 0 | B15: 0 | C15: 0 | E15: IPc2 | F15: Green Leases | I15: 6 | J15: =SUM(A15:B15) -> 0 | K15: =IF(J15>I15,"⚠","")
E17: Location and Transportation (LT) | I17: =SUM(I18:I22) -> 15 | J17: =SUM(J18:J22) -> 0
A18: 0 | B18: 0 | C18: 0 | E18: LTc1 | F18: Sensitive Land Protection | I18: 1 | J18: =SUM(A18:B18) -> 0 | K18: =IF(J18>I18,"⚠","")
A19: 0 | B19: 0 | C19: 0 | E19: LTc2 | F19: Equitable Development | I19: 2 | J19: =SUM(A19:B19) -> 0 | K19: =IF(J19>I19,"⚠","")
A20: 0 | B20: 0 | C20: 0 | E20: LTc3 | F20: Compact and Connected Development | I20: 6 | J20: =SUM(A20:B20) -> 0 | K20: =IF(J20>I20,"⚠","")
A21: 0 | B21: 0 | C21: 0 | E21: LTc4 | F21: Transportation Demand Management | I21: 4 | J21: =SUM(A21:B21) -> 0 | K21: =IF(J21>I21,"⚠","")
A22: 0 | B22: 0 | C22: 0 | E22: LTc5 | F22: Electric Vehicles | I22: 2 | J22: =SUM(A22:B22) -> 0 | K22: =IF(J22>I22,"⚠","")
E24: Sustainable Sites (SS) | I24: =SUM(I26:I31) -> 11 | J24: =SUM(J26:J31) -> 0
A25: FALSE | B25: FALSE | C25: FALSE | E25: SSp1 | F25: Minimize Site Disturbance | I25: Required | J25: Required
A26: 0 | B26: 0 | C26: 0 | E26: SSc1 | F26: Biodiverse Habitat | I26: 2 | J26: =SUM(A26:B26) -> 0 | K26: =IF(J26>I26,"⚠","")
A27: 0 | B27: 0 | C27: 0 | E27: SSc2 | F27: Accessible Outdoor Space | I27: 1 | J27: =SUM(A27:B27) -> 0 | K27: =IF(J27>I27,"⚠","")
A28: 0 | B28: 0 | C28: 0 | E28: SSc3 | F28: Rainwater Management | I28: 3 | J28: =SUM(A28:B28) -> 0 | K28: =IF(J28>I28,"⚠","")
A29: 0 | B29: 0 | C29: 0 | E29: SSc4 | F29: Enhanced Resilient Site Design | I29: 2 | J29: =SUM(A29:B29) -> 0 | K29: =IF(J29>I29,"⚠","")
A30: 0 | B30: 0 | C30: 0 | E30: SSc5 | F30: Heat Island Reduction | I30: 2 | J30: =SUM(A30:B30) -> 0 | K30: =IF(J30>I30,"⚠","")
A31: 0 | B31: 0 | C31: 0 | E31: SSc6 | F31: Light Pollution Reduction | I31: 1 | J31: =SUM(A31:B31) -> 0 | K31: =IF(J31>I31,"⚠","")
E33: Water Efficiency (WE) | I33: =SUM(I36:I37) -> 8 | J33: =SUM(J36:J37) -> 0
A34: FALSE | B34: FALSE | C34: FALSE | E34: WEp1 | F34: Water Metering and Reporting | I34: Required | J34: Required
A35: FALSE | B35: FALSE | C35: FALSE | E35: WEp2 | F35: Minimum Water Efficiency | I35: Required | J35: Required
A36: 0 | B36: 0 | C36: 0 | E36: WEc1 | F36: Water Metering and Leak Detection | I36: 1 | J36: =SUM(A36:B36) -> 0 | K36: =IF(J36>I36,"⚠","")
A37: 0 | B37: 0 | C37: 0 | E37: WEc2 | F37: Enhanced Water Efficiency | I37: 7 | J37: =SUM(A37:B37) -> 0 | K37: =IF(J37>I37,"⚠","")
E39: Energy and Atmosphere (EA) | I39: =SUM(I45:I51) -> 27 | J39: =SUM(J45:J51) -> 0
A40: FALSE | B40: FALSE | C40: FALSE | E40: EAp1 | F40: Operational Carbon Projection and Decarbonization Plan | I40: Required | J40: Required
A41: FALSE | B41: FALSE | C41: FALSE | E41: EAp2 | F41: Minimum Energy Efficiency | I41: Required | J41: Required
A42: FALSE | B42: FALSE | C42: FALSE | E42: EAp3 | F42: Fundamental Commissioning | I42: Required | J42: Required
A43: FALSE | B43: FALSE | C43: FALSE | E43: EAp4 | F43: Energy Metering and Reporting | I43: Required | J43: Required
A44: FALSE | B44: FALSE | C44: FALSE | E44: EAp5 | F44: Fundamental Refrigerant Management | I44: Required | J44: Required
A45: 0 | B45: 0 | C45: 0 | E45: EAc1 | F45: Electrification | I45: 4 | J45: =SUM(A45:B45) -> 0 | K45: =IF(J45>I45,"⚠","")
...

Sheet BD+C impact area view 
A2: LEED v5 for Building Design and Construction: Core and Shell
A3: Project scorecard
A4: Yes | B4: Maybe | C4: No | I4: Yes | J4: Maybe | K4: No | Q4: Yes | R4: Maybe | S4: No
A5: Decarbonization | I5: Quality of Life | Q5: Ecological Conservation and Restoration
A6: ='BD+C credit category view'!A12 -> FALSE | B6: ='BD+C credit category view'!B12 -> FALSE | C6: ='BD+C credit category view'!C12 -> FALSE | D6: IP Prereq | E6: ='BD+C credit category view'!E12 -> IPp3 | F6: Carbon Assessment | I6: ='BD+C credit category view'!A10 -> FALSE | J6: ='BD+C credit category view'!B10 -> FALSE | K6: ='BD+C credit category view'!C10 -> FALSE | L6: IP Prereq | M6: ='BD+C credit category view'!E10 -> IPp1 | N6: Climate Resilience Assessment | Q6: =I7 -> FALSE | R6: =J7 -> FALSE | S6: =K7 -> FALSE | T6: IP Prereq | U6: =M7 -> IPp4 | V6: Tenant Guidelines
A7: ='BD+C credit category view'!A13 -> FALSE | B7: ='BD+C credit category view'!B13 -> FALSE | C7: ='BD+C credit category view'!C13 -> FALSE | D7: IP Prereq | E7: ='BD+C credit category view'!E13 -> IPp4 | F7: Tenant Guidelines | I7: =A7 -> FALSE | J7: =B7 -> FALSE | K7: =C7 -> FALSE | L7: IP Prereq | M7: ='BD+C credit category view'!E13 -> IPp4 | N7: Tenant Guidelines | Q7: =I9 -> FALSE | R7: =J9 -> FALSE | S7: =K9 -> FALSE | T7: IP Credit | U7: =M9 -> IPc1 | V7: Integrative Design Process | W7: =G8
A8: ='BD+C credit category view'!A14>0 -> FALSE | B8: ='BD+C credit category view'!B14>0 -> FALSE | C8: ='BD+C credit category view'!C14>0 -> FALSE | D8: IP Credit | E8: ='BD+C credit category view'!E14 -> IPc1 | F8: Integrative Design Process | G8: ='BD+C credit category view'!K14 | I8: ='BD+C credit category view'!A11 -> FALSE | J8: ='BD+C credit category view'!B11 -> FALSE | K8: ='BD+C credit category view'!C11 -> FALSE | L8: IP Prereq | M8: ='BD+C credit category view'!E11 -> IPp2 | N8: Human Impact Assessment | Q8: =I10 -> FALSE | R8: =J10 -> FALSE | S8: =K10 -> FALSE | T8: IP Credit | U8: =E9 -> IPc2 | V8: Green Leases | W8: =G9
A9: ='BD+C credit category view'!A15>0 -> FALSE | B9: ='BD+C credit category view'!B15>0 -> FALSE | C9: ='BD+C credit category view'!C15>0 -> FALSE | D9: IP Credit | E9: ='BD+C credit category view'!E15 -> IPc2 | F9: Green Leases | G9: ='BD+C credit category view'!K15 | I9: =A8 -> FALSE | J9: =B8 -> FALSE | K9: =C8 -> FALSE | L9: IP Credit | M9: ='BD+C credit category view'!E14 -> IPc1 | N9: Integrative Design Process | O9: =G8 | Q9: ='BD+C credit category view'!A18>0 -> FALSE | R9: ='BD+C credit category view'!B18>0 -> FALSE | S9: ='BD+C credit category view'!C18>0 -> FALSE | T9: LT Credit | U9: ='BD+C credit category view'!E18 -> LTc1 | V9: Sensitive Land Protection | W9: ='BD+C credit category view'!K18
A10: ='BD+C credit category view'!A20>0 -> FALSE | B10: ='BD+C credit category view'!B20>0 -> FALSE | C10: ='BD+C credit category view'!C20>0 -> FALSE | D10: LT Credit | E10: ='BD+C credit category view'!E20 -> LTc3 | F10: Compact and Connected Development | G10: ='BD+C credit category view'!K20 | I10: =A9 -> FALSE | J10: =B9 -> FALSE | K10: =C9 -> FALSE | L10: IP Credit | M10: ='BD+C credit category view'!E15 -> IPc2 | N10: Green Leases | O10: =G9 | Q10: =I12 -> FALSE | R10: =J12 -> FALSE | S10: =K12 -> FALSE | T10: LT Credit | U10: =E10 -> LTc3 | V10: Compact and Connected Development | W10: =G10
A11: ='BD+C credit category view'!A21>0 -> FALSE | B11: ='BD+C credit category view'!B21>0 -> FALSE | C11: ='BD+C credit category view'!C21>0 -> FALSE | D11: LT Credit | E11: ='BD+C credit category view'!E21 -> LTc4 | F11: Transportation Demand Management | G11: ='BD+C credit category view'!K21 | I11: ='BD+C credit category view'!A19>0 -> FALSE | J11: ='BD+C credit category view'!B19>0 -> FALSE | K11: ='BD+C credit category view'!C19>0 -> FALSE | L11: LT Credit | M11: ='BD+C credit category view'!E19 -> LTc2 | N11: Equitable Development | O11: ='BD+C credit category view'!K19 | Q11: ='BD+C credit category view'!A25 -> FALSE | R11: ='BD+C credit category view'!B25 -> FALSE | S11: ='BD+C credit category view'!C25 -> FALSE | T11: SS Prereq | U11: ='BD+C credit category view'!E25 -> SSp1 | V11: Minimized Site Disturbance
A12: ='BD+C credit category view'!A22>0 -> FALSE | B12: ='BD+C credit category view'!B22>0 -> FALSE | C12: ='BD+C credit category view'!C22>0 -> FALSE | D12: LT Credit | E12: ='BD+C credit category view'!E22 -> LTc5 | F12: Electric Vehicles | G12: ='BD+C credit category view'!K22 | I12: ='BD+C credit category view'!A20>0 -> FALSE | J12: ='BD+C credit category view'!B20>0 -> FALSE | K12: ='BD+C credit category view'!C20>0 -> FALSE | L12: LT Credit | M12: ='BD+C credit category view'!E20 -> LTc3 | N12: Compact and Connected Development | O12: =G10 | Q12: ='BD+C credit category view'!A26>0 -> FALSE | R12: ='BD+C credit category view'!B26>0 -> FALSE | S12: ='BD+C credit category view'!C26>0 -> FALSE | T12: SS Credit | U12: ='BD+C credit category view'!E26 -> SSc1 | V12: Biodiverse Habitat | W12: ='BD+C credit category view'!K26
A13: ='BD+C credit category view'!A30>0 -> FALSE | B13: ='BD+C credit category view'!B30>0 -> FALSE | C13: ='BD+C credit category view'!C30>0 -> FALSE | D13: SS Credit | E13: ='BD+C credit category view'!E30 -> SSc5 | F13: Heat Island Reduction | G13: ='BD+C credit category view'!K30 | I13: ='BD+C credit category view'!A21>0 -> FALSE | J13: ='BD+C credit category view'!B21>0 -> FALSE | K13: ='BD+C credit category view'!C21>0 -> FALSE | L13: LT Credit | M13: ='BD+C credit category view'!E21 -> LTc4 | N13: Transportation Demand Management | O13: =G11 | Q13: ='BD+C credit category view'!A27>0 -> FALSE | R13: ='BD+C credit category view'!B27>0 -> FALSE | S13: ='BD+C credit category view'!C27>0 -> FALSE | T13: SS Credit | U13: ='BD+C credit category view'!E27 -> SSc2 | V13: Accessible Outdoor Space | W13: ='BD+C credit category view'!K27
A14: ='BD+C credit category view'!A35 -> FALSE | B14: ='BD+C credit category view'!B35 -> FALSE | C14: ='BD+C credit category view'!C35 -> FALSE | D14: WE Prereq | E14: ='BD+C credit category view'!E35 -> WEp2 | F14: Minimum Water Efficiency | I14: ='BD+C credit category view'!A27>0 -> FALSE | J14: ='BD+C credit category view'!B27>0 -> FALSE | K14: ='BD+C credit category view'!C27>0 -> FALSE | L14: SS Credit | M14: ='BD+C credit category view'!E27 -> SSc2 | N14: Accessible Outdoor Space | O14: ='BD+C credit category view'!K27 | Q14: ='BD+C credit category view'!A28>0 -> FALSE | R14: ='BD+C credit category view'!B28>0 -> FALSE | S14: ='BD+C credit category view'!C28>0 -> FALSE | T14: SS Credit | U14: ='BD+C credit category view'!E28 -> SSc3 | V14: Rainwater Management | W14: ='BD+C credit category view'!K28
A15: ='BD+C credit category view'!A36>0 -> FALSE | B15: ='BD+C credit category view'!B36>0 -> FALSE | C15: ='BD+C credit category view'!C36>0 -> FALSE | D15: WE Credit | E15: ='BD+C credit category view'!E36 -> WEc1 | F15: Water Metering and Leak Detection | G15: ='BD+C credit category view'!K36 | I15: ='BD+C credit category view'!A29>0 -> FALSE | J15: ='BD+C credit category view'!B29>0 -> FALSE | K15: ='BD+C credit category view'!C29>0 -> FALSE | L15: SS Credit | M15: ='BD+C credit category view'!E29 -> SSc4 | N15: Enhanced Resilient Site Design | O15: ='BD+C credit category view'!K29 | Q15: ='BD+C credit category view'!A29>0 -> FALSE | R15: ='BD+C credit category view'!B29>0 -> FALSE | S15: ='BD+C credit category view'!C29>0 -> FALSE | T15: SS Credit | U15: ='BD+C credit category view'!E29 -> SSc4 | V15: Enhanced Resilient Site Design | W15: ='BD+C credit category view'!K29
A16: ='BD+C credit category view'!A37>0 -> FALSE | B16: ='BD+C credit category view'!B37>0 -> FALSE | C16: ='BD+C credit category view'!C37>0 -> FALSE | D16: WE Credit | E16: ='BD+C credit category view'!E37 -> WEc2 | F16: Enhanced Water Efficiency | G16: ='BD+C credit category view'!K37 | I16: ='BD+C credit category view'!A30>0 -> FALSE | J16: ='BD+C credit category view'!B30>0 -> FALSE | K16: ='BD+C credit category view'!C30>0 -> FALSE | L16: SS Credit | M16: ='BD+C credit category view'!E30 -> SSc5 | N16: Heat Island Reduction | O16: ='BD+C credit category view'!K30 | Q16: ='BD+C credit category view'!A30>0 -> FALSE | R16: ='BD+C credit category view'!B30>0 -> FALSE | S16: ='BD+C credit category view'!C30>0 -> FALSE | T16: SS Credit | U16: ='BD+C credit category view'!E30 -> SSc5 | V16: Heat Island Reduction | W16: ='BD+C credit category view'!K30
A17: ='BD+C credit category view'!A40 -> FALSE | B17: ='BD+C credit category view'!B40 -> FALSE | C17: ='BD+C credit category view'!C40 -> FALSE | D17: EA Prereq | E17: ='BD+C credit category view'!E40 -> EAp1 | F17: Operational Carbon Projection and Decarbonization Plan | I17: =A15 -> FALSE | J17: =B15 -> FALSE | K17: =C15 -> FALSE | L17: WE Credit | M17: ='BD+C credit category view'!E34 -> WEp1 | N17: Water Metering and Leak Detection | O17: ='BD+C credit category view'!K36 | Q17: ='BD+C credit category view'!A31>0 -> FALSE | R17: ='BD+C credit category view'!B31>0 -> FALSE | S17: ='BD+C credit category view'!C31>0 -> FALSE | T17: SS Credit | U17: ='BD+C credit category view'!E31 -> SSc6 | V17: Light Pollution Reduction | W17: ='BD+C credit category view'!K31
A18: ='BD+C credit category view'!A41 -> FALSE | B18: ='BD+C credit category view'!B41 -> FALSE | C18: ='BD+C credit category view'!C41 -> FALSE | D18: EA Prereq | E18: ='BD+C credit category view'!E41 -> EAp2 | F18: Minimum Energy Efficiency | I18: ='BD+C credit category view'!A58>0 -> FALSE | J18: ='BD+C credit category view'!B58>0 -> FALSE | K18: ='BD+C credit category view'!C58>0 -> FALSE | L18: MR Credit | M18: ='BD+C credit category view'!E58 -> MRc3 | N18: Low Emitting Materials | O18: ='BD+C credit category view'!K58 | Q18: ='BD+C credit category view'!A34 -> FALSE | R18: ='BD+C credit category view'!B34 -> FALSE | S18: ='BD+C credit category view'!C34 -> FALSE | T18: WE Prereq | U18: ='BD+C credit category view'!E34 -> WEp1 | V18: Water Metering and Reporting
A19: ='BD+C credit category view'!A42 -> FALSE | B19: ='BD+C credit category view'!B42 -> FALSE | C19: ='BD+C credit category view'!C42 -> FALSE | D19: EA Prereq | E19: ='BD+C credit category view'!E42 -> EAp3 | F19: Fundamental Commissioning | I19: ='BD+C credit category view'!A59>0 -> FALSE | J19: ='BD+C credit category view'!B59>0 -> FALSE | K19: ='BD+C credit category view'!C59>0 -> FALSE | L19: MR Credit | M19: ='BD+C credit category view'!E59 -> MRc4 | N19: Building Product Selection and Procurement | O19: ='BD+C credit category view'!K59 | Q19: ='BD+C credit category view'!A35 -> FALSE | R19: ='BD+C credit category view'!B35 -> FALSE | S19: ='BD+C credit category view'!C35 -> FALSE | T19: WE Prereq | U19: ='BD+C credit category view'!E35 -> WEp2 | V19: Minimum Water Efficiency
A20: ='BD+C credit category view'!A43 -> FALSE | B20: ='BD+C credit category view'!B43 -> FALSE | C20: ='BD+C credit category view'!C43 -> FALSE | D20: EA Prereq | E20: ='BD+C credit category view'!E43 -> EAp4 | F20: Energy Metering and Reporting | I20: ='BD+C credit category view'!A63 -> FALSE | J20: ='BD+C credit category view'!B63 -> FALSE | K20: ='BD+C credit category view'!C63 -> FALSE | L20: EQ Prereq | M20: ='BD+C credit category view'!E63 -> EQp1 | N20: Construction Management | Q20: =A15 -> FALSE | R20: =B15 -> FALSE | S20: =C15 -> FALSE | T20: WE Credit | U20: ='BD+C credit category view'!E36 -> WEc1 | V20: Water Metering and Leak Detection | W20: =G15
A21: ='BD+C credit category view'!A44 -> FALSE | B21: ='BD+C credit category view'!B44 -> FALSE | C21: ='BD+C credit category view'!C44 -> FALSE | D21: EA Prereq | E21: ='BD+C credit category view'!E44 -> EAp5 | F21: Fundamental Refrigerant Management | I21: ='BD+C credit category view'!A64 -> FALSE | J21: ='BD+C credit category view'!B64 -> FALSE | K21: ='BD+C credit category view'!C64 -> FALSE | L21: EQ Prereq | M21: ='BD+C credit category view'!E64 -> EQp2 | N21: Fundamental Air Quality | Q21: =A16 -> FALSE | R21: =B16 -> FALSE | S21: =C16 -> FALSE | T21: WE Credit | U21: ='BD+C credit category view'!E37 -> WEc2 | V21: Enhanced Water Efficiency | W21: =G16
A22: ='BD+C credit category view'!A45>0 -> FALSE | B22: ='BD+C credit category view'!B45>0 -> FALSE | C22: ='BD+C credit category view'!C45>0 -> FALSE | D22: EA Credit | E22: ='BD+C credit category view'!E45 -> EAc1 | F22: Electrification | G22: ='BD+C credit category view'!K45 | I22: ='BD+C credit category view'!A65 -> FALSE | J22: ='BD+C credit category view'!B65 -> FALSE | K22: ='BD+C credit category view'!C65 -> FALSE | L22: EQ Prereq | M22: ='BD+C credit category view'!E65 -> EQp3 | N22: No Smoking or Vehicle Idling | Q22: =A29 -> FALSE | R22: =B29 -> FALSE | S22: =C29 -> FALSE | T22: MR Prereq | U22: ='BD+C credit category view'!E54 -> MRp1 | V22: Planning for Zero Waste Operations
A23: ='BD+C credit category view'!A46>0 -> FALSE | B23: ='BD+C credit category view'!B46>0 -> FALSE | C23: ='BD+C credit category view'!C46>0 -> FALSE | D23: EA Credit | E23: ='BD+C credit category view'!E46 -> EAc2 | F23: Reduce Peak Thermal Loads | G23: ='BD+C credit category view'!K46 | I23: ='BD+C credit category view'!A66>0 -> FALSE | J23: ='BD+C credit category view'!B66>0 -> FALSE | K23: ='BD+C credit category view'!C66>0 -> FALSE | L23: EQ Credit | M23: ='BD+C credit category view'!E66 -> EQc1 | N23: Enhanced Air Quality | O23: ='BD+C credit category view'!K66 | Q23: =A31 -> FALSE | R23: =B31 -> FALSE | S23: =C31 -> FALSE | T23: MR Credit | U23: ='BD+C credit category view'!E56 -> MRc1 | V23: Building and Materials Reuse | W23: =G31
A24: ='BD+C credit category view'!A47>0 -> FALSE | B24: ='BD+C credit category view'!B47>0 -> FALSE | C24: ='BD+C credit category view'!C47>0 -> FALSE | D24: EA Credit | E24: ='BD+C credit category view'!E47 -> EAc3 | F24: Enhanced Energy Efficiency | G24: ='BD+C credit category view'!K47 | I24: ='BD+C credit category view'!A67>0 -> FALSE | J24: ='BD+C credit category view'!B67>0 -> FALSE | K24: ='BD+C credit category view'!C67>0 -> FALSE | L24: EQ Credit | M24: ='BD+C credit category view'!E67 -> EQc2 | N24: Occupant Experience | O24: ='BD+C credit category view'!K67 | Q24: =A33 -> FALSE | R24: =B33 -> FALSE | S24: =C33 -> FALSE | T24: MR Credit | U24: ='BD+C credit category view'!E59 -> MRc4 | V24: Building Product Selection and Procurement | W24: =G33
A25: ='BD+C credit category view'!A48>0 -> FALSE | B25: ='BD+C credit category view'!B48>0 -> FALSE | C25: ='BD+C credit category view'!C48>0 -> FALSE | D25: EA Credit | E25: ='BD+C credit category view'!E48 -> EAc4 | F25: Renewable Energy | G25: ='BD+C credit category view'!K48 | I25: ='BD+C credit category view'!A68>0 -> FALSE | J25: ='BD+C credit category view'!B68>0 -> FALSE | K25: ='BD+C credit category view'!C68>0 -> FALSE | L25: EQ Credit | M25: ='BD+C credit category view'!E68 -> EQc3 | N25: Accessibility and Inclusion | O25: ='BD+C credit category view'!K68 | Q25: =A34 -> FALSE | R25: =B34 -> FALSE | S25: =C34 -> FALSE | T25: MR Credit | U25: ='BD+C credit category view'!E60 -> MRc5 | V25: Construction and Demolition Waste Diversion | W25: =G34
A26: ='BD+C credit category view'!A49>0 -> FALSE | B26: ='BD+C credit category view'!B49>0 -> FALSE | C26: ='BD+C credit category view'!C49>0 -> FALSE | D26: EA Credit | E26: ='BD+C credit category view'!E49 -> EAc5 | F26: Enhanced Commissioning | G26: ='BD+C credit category view'!K49 | I26: ='BD+C credit category view'!A69>0 -> FALSE | J26: ='BD+C credit category view'!B69>0 -> FALSE | K26: ='BD+C credit category view'!C69>0 -> FALSE | L26: EQ Credit | M26: ='BD+C credit category view'!E69 -> EQc4 | N26: Resilient Spaces | O26: ='BD+C credit category view'!K69 | Q26: =I22 -> FALSE | R26: =J22 -> FALSE | S26: =K22 -> FALSE | T26: EQ Prereq | U26: =M22 -> EQp3 | V26: No Smoking or Vehicle Idling
A27: ='BD+C credit category view'!A50>0 -> FALSE | B27: ='BD+C credit category view'!B50>0 -> FALSE | C27: ='BD+C credit category view'!C50>0 -> FALSE | D27: EA Credit | E27: ='BD+C credit category view'!E50 -> EAc6 | F27: Grid Interactive | G27: ='BD+C credit category view'!K50
A28: ='BD+C credit category view'!A51>0 -> FALSE | B28: ='BD+C credit category view'!B51>0 -> FALSE | C28: ='BD+C credit category view'!C51>0 -> FALSE | D28: EA Credit | E28: ='BD+C credit category view'!E51 -> EAc7 | F28: Enhanced Refrigerant Management | G28: ='BD+C credit category view'!K51
A29: ='BD+C credit category view'!A54 -> FALSE | B29: ='BD+C credit category view'!B54 -> FALSE | C29: ='BD+C credit category view'!C54 -> FALSE | D29: MR Prereq | E29: ='BD+C credit category view'!E54 -> MRp1 | F29: Planning for Zero Waste Operations
A30: ='BD+C credit category view'!A55 -> FALSE | B30: ='BD+C credit category view'!B55 -> FALSE | C30: ='BD+C credit category view'!C55 -> FALSE | D30: MR Prereq | E30: ='BD+C credit category view'!E55 -> MRp2 | F30: Quantify and Assess Embodied Carbon
A31: ='BD+C credit category view'!A56>0 -> FALSE | B31: ='BD+C credit category view'!B56>0 -> FALSE | C31: ='BD+C credit category view'!C56>0 -> FALSE | D31: MR Credit | E31: ='BD+C credit category view'!E56 -> MRc1 | F31: Building and Materials Reuse | G31: ='BD+C credit category view'!K56
A32: ='BD+C credit category view'!A57>0 -> FALSE | B32: ='BD+C credit category view'!B57>0 -> FALSE | C32: ='BD+C credit category view'!C57>0 -> FALSE | D32: MR Credit | E32: ='BD+C credit category view'!E57 -> MRc2 | F32: Reduce Embodied Carbon | G32: ='BD+C credit category view'!K57
A33: ='BD+C credit category view'!A59>0 -> FALSE | B33: ='BD+C credit category view'!B59>0 -> FALSE | C33: ='BD+C credit category view'!C59>0 -> FALSE | D33: MR Credit | E33: ='BD+C credit category view'!E59 -> MRc4 | F33: Building Product Selection and Procurement | G33: ='BD+C credit category view'!K59
A34: ='BD+C credit category view'!A60>0 -> FALSE | B34: ='BD+C credit category view'!B60>0 -> FALSE | C34: ='BD+C credit category view'!C60>0 -> FALSE | D34: MR Credit | E34: ='BD+C credit category view'!E60 -> MRc5 | F34: Construction and Demolition Waste Diversion | G34: ='BD+C credit category view'!K60

Sheet Analytics
A2: LEED v5 for Building Design and Construction: Core and Shell
A3: Project scorecard analytics

Sheet Background
A1: Data Validation
A2: Yes | J2: Yes | K2: ='BD+C credit category view'!M2 -> 0
A3: Maybe | J3: Maybe | K3: ='BD+C credit category view'!M3 -> 0
A4: No | J4: No | K4: ='BD+C credit category view'!M4 -> 0 | Q4: Decarbonization
J5: Blank | K5: =J19-K4-K3-K2 -> 110 | Q5: Yes | R5: Maybe | S5: No | T5: Blank
J6: Related Charts | Q6: =COUNTIF('BD+C impact area view '!A6:A34, "TRUE") -> 0 | R6: =COUNTIF('BD+C impact area view '!B6:B34, "TRUE") -> 0 | S6: =COUNTIF('BD+C impact area view '!C6:C34, "TRUE") -> 0 | T6: =COUNTA('BD+C impact area view '!E6:E34)-Q6-R6-S6 -> 29
J7: Total Anticipated Points Distribution
J8: Total Anticipated Points Distribution
Q9: Quality of Life
Q10: Yes | R10: Maybe | S10: No | T10: Blank
Q11: =COUNTIF('BD+C impact area view '!I6:I26, "TRUE") -> 0 | R11: =COUNTIF('BD+C impact area view '!J6:J26, "TRUE") -> 0 | S11: =COUNTIF('BD+C impact area view '!K6:K26, "TRUE") -> 0 | T11: =COUNTA('BD+C impact area view '!M6:M26)-Q11-R11-S11 -> 21
Q13: Ecological Conservation and Restoration
Q14: Yes | R14: Maybe | S14: No | T14: Blank
E15: Total Possible Points | F15: Total Anticipated Points | Q15: =COUNTIF('BD+C impact area view '!Q6:Q26,"TRUE") -> 0 | R15: =COUNTIF('BD+C impact area view '!R6:R26,"TRUE") -> 0 | S15: =COUNTIF('BD+C impact area view '!S6:S26,"TRUE") -> 0 | T15: =COUNTA('BD+C impact area view '!U6:U26)-Q15-R15-S15 -> 21
I16: Total Anticipated Points | J16: ='BD+C credit category view'!M6 -> 0 | K16: points | Q16: Related Charts
I17: Certified Project | J17: 40 | K17: points | Q17: Anticipated Decarbonization Credits
A18: Integrative Process, Planning and Assessments (IP) | E18: ='BD+C credit category view'!I9 -> 7 | F18: ='BD+C credit category view'!J9 -> 0 | I18: Platinum Project | J18: 80 | K18: points | Q18: Anticipated Quality of Life Credits
A19: Location and Transportation (LT) | E19: ='BD+C credit category view'!I17 -> 15 | F19: ='BD+C credit category view'!J17 -> 0 | I19: Total Possible Points | J19: ='BD+C credit category view'!M7 -> 110 | K19: points | Q19: Anticipated Ecological Conservation and Restoration Credits
A20: Sustainable Sites (SS) | E20: ='BD+C credit category view'!I24 -> 11 | F20: ='BD+C credit category view'!J24 -> 0 | I20: Related Charts
A21: Water Efficiency (WE) | E21: ='BD+C credit category view'!I33 -> 8 | F21: ='BD+C credit category view'!J33 -> 0 | I21: Total Anticipated Points versus LEED Certification Levels
A22: Energy and Atmosphere (EA) | E22: ='BD+C credit category view'!I39 -> 27 | F22: ='BD+C credit category view'!J39 -> 0
A23: Materials and Resources (MR) | E23: ='BD+C credit category view'!I53 -> 21 | F23: ='BD+C credit category view'!J53 -> 0
A24: Indoor Environmental Quality (EQ) | E24: ='BD+C credit category view'!I62 -> 11 | F24: ='BD+C credit category view'!J62 -> 0
A25: Project Priorities (PR) | E25: ='BD+C credit category view'!I71 -> 10 | F25: ='BD+C credit category view'!J71 -> 0
A26: Related Charts
A27: Total Possible Points by Credit Category
A28: Total Anticipated Points by Credit Category
