Workbook

Sheet Cover
B2: LEED v5 for Interior Design and Construction: Commercial Interiors Scorecard
C3: ID+C credit category view | F3: Provides an overview of points per credit category
C4: ID+C impact area view | F4: Provides a directional indicator of the credits per impact area.
C5: Analytics | F5: Provides basic analytics derived from points, credit, and prerequisite data entered.
C7: How to use
C8: 1. Navigate to the "ID+C Credit Category View" tab
C9: 2. For each credit, enter the number of anticipated points in Columns A-C, titled "Yes", "Maybe" and "No".
D10: "Yes": Points will count towards your total.
D11: "Maybe": Points will count towards your totals.
D12: "No": Points will not count towards your totals.
C13: 3. For each prerequisite, utilize the checkbox in Columns A-C, titled "Yes", "Maybe" and "No". Please note prerequisites do not count toward point totals.
C14: 4. For Project Priorities, utilize column H to enter up to 9 credit names and anticipated points per credit.
C15: 5. "ID+C impact area view " tab will automatically update with all the decisions you made on the "ID+C Credit Category View" tab; no additional input is needed.
C16: * Feel free to customize this tool in any way that best suits your needs. Whether you need to add new columns or simply rearrange the layout to better fit your workflow, this tool is designed with flexibility in mind.

Sheet ID+C credit category view
L1: Total
A2: LEED v5 for Interior Design and Construction: Commercial Interiors | L2: Yes | M2: =A70 -> 0 | N2: points | P2: Key:
A3: Project scorecard | L3: Maybe | M3: =B70 -> 0 | N3: points | P3: Prerequisite
L4: No | M4: =C70 -> 0 | N4: points | P4: Credit
I6: Total Possible Points | J6: Total Anticipated Points | L6: Total Anticipated Points | M6: =J70 -> 0 | N6: points
L7: Total Possible Points | M7: =I70 -> 110 | N7: points
A8: Yes | B8: Maybe | C8: No | L8: Responsible Party | M8: Notes
E9: Integrative Process, Planning and Assessments (IP) | I9: =SUM(I13) -> 1 | J9: =SUM(J13) -> 0
A10: FALSE | B10: FALSE | C10: FALSE | E10: IPp1 | F10: Climate Resilience Assessment | I10: Required
A11: FALSE | B11: FALSE | C11: FALSE | E11: IPp2 | F11: Human Impact Assessment | I11: Required | J11: Required
A12: FALSE | B12: FALSE | C12: FALSE | E12: IPp3 | F12: Carbon Assessment | I12: Required | J12: Required
A13: 0 | B13: 0 | C13: 0 | E13: IPc1 | F13: Integrative Design Process | I13: 1 | J13: =SUM(A13:B13) -> 0 | K13: =IF(J13>I13,"⚠","")
E15: Location and Transportation (LT) | I15: =SUM(I16:I18) -> 14 | J15: =SUM(J16:J18) -> 0
A16: 0 | B16: 0 | C16: 0 | E16: LTc1 | F16: Compact and Connected Development | I16: 8 | J16: =SUM(A16:B16) -> 0 | K16: =IF(J16>I16,"⚠","")
A17: 0 | B17: 0 | C17: 0 | E17: LTc2 | F17: Transportation Demand Management | I17: 4 | J17: =SUM(A17:B17) -> 0 | K17: =IF(J17>I17,"⚠","")
A18: 0 | B18: 0 | C18: 0 | E18: LTc3 | F18: Electric Vehicles | I18: 2 | J18: =SUM(A18:B18) -> 0 | K18: =IF(J18>I18,"⚠","")
E20: Water Efficiency (WE) | I20: =SUM(I22:I23) -> 10 | J20: =SUM(J22:J23) -> 0
A21: FALSE | B21: FALSE | C21: FALSE | E21: WEp1 | F21: Minimum Water Efficiency | I21: Required | J21: Required
A22: 0 | B22: 0 | C22: 0 | E22: WEc1 | F22: Water Metering and Leak Detection | I22: 2 | J22: =SUM(A22:B22) -> 0 | K22: =IF(J22>I22,"⚠","")
A23: 0 | B23: 0 | C23: 0 | E23: WEc2 | F23: Enhanced Water Efficiency | I23: 8 | J23: =SUM(A23:B23) -> 0 | K23: =IF(J23>I23,"⚠","")
E25: Energy and Atmosphere (EA) | I25: =SUM(I31:I36) -> 31 | J25: =SUM(J31:J36) -> 0
A26: FALSE | B26: FALSE | C26: FALSE | E26: EAp1 | F26: Estimated Energy Use and Operational Carbon Projection | I26: Required | J26: Required
A27: FALSE | B27: FALSE | C27: FALSE | E27: EAp2 | F27: Minimum Energy Efficiency | I27: Required | J27: Required
A28: FALSE | B28: FALSE | C28: FALSE | E28: EAp3 | F28: Fundamental Commissioning | I28: Required | J28: Required
A29: FALSE | B29: FALSE | C29: FALSE | E29: EAp4 | F29: Energy Metering and Reporting | I29: Required | J29: Required
A30: FALSE | B30: FALSE | C30: FALSE | E30: EAp5 | F30: Fundamental Refrigerant Management | I30: Required | J30: Required
A31: 0 | B31: 0 | C31: 0 | E31: EAc1 | F31: Electrification | I31: 5 | J31: =SUM(A31:B31) -> 0 | K31: =IF(J31>I31,"⚠","")
A32: 0 | B32: 0 | C32: 0 | E32: EAc2 | F32: Enhanced Energy Efficiency | I32: 12 | J32: =SUM(A32:B32) -> 0 | K32: =IF(J32>I32,"⚠","")
A33: 0 | B33: 0 | C33: 0 | E33: EAc3 | F33: Renewable Energy | I33: 5 | J33: =SUM(A33:B33) -> 0 | K33: =IF(J33>I33,"⚠","")
A34: 0 | B34: 0 | C34: 0 | E34: EAc4 | F34: Enhanced Commissioning | I34: 4 | J34: =SUM(A34:B34) -> 0 | K34: =IF(J34>I34,"⚠","")
A35: 0 | B35: 0 | C35: 0 | E35: EAc5 | F35: Grid Interactive | I35: 3 | J35: =SUM(A35:B35) -> 0 | K35: =IF(J35>I35,"⚠","")
A36: 0 | B36: 0 | C36: 0 | E36: EAc6 | F36: Enhanced Refrigerant Management | I36: 2 | J36: =SUM(A36:B36) -> 0 | K36: =IF(J36>I36,"⚠","")
E38: Materials and Resources (MR) | I38: =SUM(I41:I45) -> 26 | J38: =SUM(J41:J45) -> 0
A39: FALSE | B39: FALSE | C39: FALSE | E39: MRp1 | F39: Planning for Zero Waste Operations | I39: Required
A40: FALSE | B40: FALSE | C40: FALSE | E40: MRp2 | F40: Quantify and Assess Embodied Carbon | I40: Required
A41: 0 | B41: 0 | C41: 0 | E41: MRc1 | F41: Interior Materials Reuse | I41: 4 | J41: =SUM(A41:B41) -> 0 | K41: =IF(J41>I41,"⚠","")
A42: 0 | B42: 0 | C42: 0 | E42: MRc2 | F42: Reduce Embodied Carbon | I42: 4 | J42: =SUM(A42:B42) -> 0 | K42: =IF(J42>I42,"⚠","")
A43: 0 | B43: 0 | C43: 0 | E43: MRc3 | F43: Low-Emitting Materials | I43: 4 | J43: =SUM(A43:B43) -> 0 | K43: =IF(J43>I43,"⚠","")
A44: 0 | B44: 0 | C44: 0 | E44: MRc4 | F44: Building Product Selection and Procurement | I44: 10 | J44: =SUM(A44:B44) -> 0 | K44: =IF(J44>I44,"⚠","")
A45: 0 | B45: 0 | C45: 0 | E45: MRc5 | F45: Construction and Demolition Waste Diversion | I45: 4 | J45: =SUM(A45:B45) -> 0 | K45: =IF(J45>I45,"⚠","")
...

Sheet ID+C impact area view 
A2: LEED v5 for Interior Design and Construction: Commercial Interiors
A3: Project scorecard
A4: Yes | B4: Maybe | C4: No | I4: Yes | J4: Maybe | K4: No | Q4: Yes | R4: Maybe | S4: No
A5: Decarbonization | I5: Quality of Life | Q5: Ecological Conservation and Restoration
A6: ='ID+C credit category view'!A12 -> FALSE | B6: ='ID+C credit category view'!B12 -> FALSE | C6: ='ID+C credit category view'!C12 -> FALSE | D6: IP Prereq | E6: ='ID+C credit category view'!E12 -> IPp3 | F6: ='ID+C credit category view'!F12 -> Carbon Assessment | I6: ='ID+C credit category view'!A10 -> FALSE | J6: ='ID+C credit category view'!B10 -> FALSE | K6: ='ID+C credit category view'!C10 -> FALSE | L6: IP Prereq | M6: ='ID+C credit category view'!E10 -> IPp1 | N6: ='ID+C credit category view'!F10 -> Climate Resilience Assessment | Q6: ='ID+C credit category view'!A13>0 -> FALSE | R6: ='ID+C credit category view'!B13>0 -> FALSE | S6: ='ID+C credit category view'!C13>0 -> FALSE | T6: IP Credit | U6: ='ID+C credit category view'!E13 -> IPc1 | V6: ='ID+C credit category view'!F13 -> Integrative Design Process | W6: ='ID+C credit category view'!K13
A7: ='ID+C credit category view'!A13>0 -> FALSE | B7: ='ID+C credit category view'!B13>0 -> FALSE | C7: ='ID+C credit category view'!C13>0 -> FALSE | D7: IP Credit | E7: ='ID+C credit category view'!E13 -> IPc1 | F7: ='ID+C credit category view'!F13 -> Integrative Design Process | G7: ='ID+C credit category view'!K13 | I7: ='ID+C credit category view'!A11 -> FALSE | J7: ='ID+C credit category view'!B11 -> FALSE | K7: ='ID+C credit category view'!C11 -> FALSE | L7: IP Prereq | M7: ='ID+C credit category view'!E11 -> IPp2 | N7: ='ID+C credit category view'!F11 -> Human Impact Assessment | Q7: ='ID+C credit category view'!A16>0 -> FALSE | R7: ='ID+C credit category view'!B16>0 -> FALSE | S7: ='ID+C credit category view'!C16>0 -> FALSE | T7: LT Credit | U7: ='ID+C credit category view'!E16 -> LTc1 | V7: ='ID+C credit category view'!F16 -> Compact and Connected Development | W7: ='ID+C credit category view'!K16
A8: ='ID+C credit category view'!A16>0 -> FALSE | B8: ='ID+C credit category view'!B16>0 -> FALSE | C8: ='ID+C credit category view'!C16>0 -> FALSE | D8: LT Credit | E8: ='ID+C credit category view'!E16 -> LTc1 | F8: ='ID+C credit category view'!F16 -> Compact and Connected Development | G8: ='ID+C credit category view'!K16 | I8: ='ID+C credit category view'!A13>0 -> FALSE | J8: ='ID+C credit category view'!B13>0 -> FALSE | K8: ='ID+C credit category view'!C13>0 -> FALSE | L8: IP Credit | M8: ='ID+C credit category view'!E13 -> IPc1 | N8: ='ID+C credit category view'!F13 -> Integrative Design Process | O8: ='ID+C credit category view'!K13 | Q8: ='ID+C credit category view'!A21 -> FALSE | R8: ='ID+C credit category view'!B21 -> FALSE | S8: ='ID+C credit category view'!C21 -> FALSE | T8: WE Prereq | U8: ='ID+C credit category view'!E21 -> WEp1 | V8: ='ID+C credit category view'!F21 -> Minimum Water Efficiency
A9: ='ID+C credit category view'!A17>0 -> FALSE | B9: ='ID+C credit category view'!B17>0 -> FALSE | C9: ='ID+C credit category view'!C17>0 -> FALSE | D9: LT Credit | E9: ='ID+C credit category view'!E17 -> LTc2 | F9: ='ID+C credit category view'!F17 -> Transportation Demand Management | G9: ='ID+C credit category view'!K17 | I9: ='ID+C credit category view'!A16>0 -> FALSE | J9: ='ID+C credit category view'!B16>0 -> FALSE | K9: ='ID+C credit category view'!C16>0 -> FALSE | L9: LT Credit | M9: ='ID+C credit category view'!E16 -> LTc1 | N9: ='ID+C credit category view'!F16 -> Compact and Connected Development | O9: ='ID+C credit category view'!K16 | Q9: ='ID+C credit category view'!A22>0 -> FALSE | R9: ='ID+C credit category view'!B22>0 -> FALSE | S9: ='ID+C credit category view'!C22>0 -> FALSE | T9: WE Credit | U9: ='ID+C credit category view'!E22 -> WEc1 | V9: ='ID+C credit category view'!F22 -> Water Metering and Leak Detection | W9: ='ID+C credit category view'!K22
A10: ='ID+C credit category view'!A18>0 -> FALSE | B10: ='ID+C credit category view'!B18>0 -> FALSE | C10: ='ID+C credit category view'!C18>0 -> FALSE | D10: LT Credit | E10: ='ID+C credit category view'!E18 -> LTc3 | F10: ='ID+C credit category view'!F18 -> Electric Vehicles | G10: ='ID+C credit category view'!K18 | I10: ='ID+C credit category view'!A17>0 -> FALSE | J10: ='ID+C credit category view'!B17>0 -> FALSE | K10: ='ID+C credit category view'!C17>0 -> FALSE | L10: LT Credit | M10: ='ID+C credit category view'!E17 -> LTc2 | N10: ='ID+C credit category view'!F17 -> Transportation Demand Management | O10: ='ID+C credit category view'!K17 | Q10: ='ID+C credit category view'!A23>0 -> FALSE | R10: ='ID+C credit category view'!B23>0 -> FALSE | S10: ='ID+C credit category view'!C23>0 -> FALSE | T10: WE Credit | U10: ='ID+C credit category view'!E23 -> WEc2 | V10: ='ID+C credit category view'!F23 -> Enhanced Water Efficiency | W10: ='ID+C credit category view'!K23
A11: ='ID+C credit category view'!A21 -> FALSE | B11: ='ID+C credit category view'!B21 -> FALSE | C11: ='ID+C credit category view'!C21 -> FALSE | D11: WE Prereq | E11: ='ID+C credit category view'!E21 -> WEp1 | F11: ='ID+C credit category view'!F21 -> Minimum Water Efficiency | I11: ='ID+C credit category view'!A22>0 -> FALSE | J11: ='ID+C credit category view'!B22>0 -> FALSE | K11: ='ID+C credit category view'!C22>0 -> FALSE | L11: WE Credit | M11: ='ID+C credit category view'!E22 -> WEc1 | N11: ='ID+C credit category view'!F22 -> Water Metering and Leak Detection | O11: ='ID+C credit category view'!K22 | Q11: ='ID+C credit category view'!A39 -> FALSE | R11: ='ID+C credit category view'!B39 -> FALSE | S11: ='ID+C credit category view'!C39 -> FALSE | T11: MR Prereq | U11: ='ID+C credit category view'!E39 -> MRp1 | V11: ='ID+C credit category view'!F39 -> Planning for Zero Waste Operations
A12: ='ID+C credit category view'!A22>0 -> FALSE | B12: ='ID+C credit category view'!B22>0 -> FALSE | C12: ='ID+C credit category view'!C22>0 -> FALSE | D12: WE Credit | E12: ='ID+C credit category view'!E22 -> WEc1 | F12: ='ID+C credit category view'!F22 -> Water Metering and Leak Detection | G12: ='ID+C credit category view'!K22 | I12: ='ID+C credit category view'!A43>0 -> FALSE | J12: ='ID+C credit category view'!B43>0 -> FALSE | K12: ='ID+C credit category view'!C43>0 -> FALSE | L12: MR Credit | M12: ='ID+C credit category view'!E43 -> MRc3 | N12: ='ID+C credit category view'!F43 -> Low-Emitting Materials | O12: ='ID+C credit category view'!K43 | Q12: ='ID+C credit category view'!A41>0 -> FALSE | R12: ='ID+C credit category view'!B41>0 -> FALSE | S12: ='ID+C credit category view'!C41>0 -> FALSE | T12: MR Credit | U12: ='ID+C credit category view'!E41 -> MRc1 | V12: ='ID+C credit category view'!F41 -> Interior Materials Reuse | W12: ='ID+C credit category view'!K41
A13: ='ID+C credit category view'!A23>0 -> FALSE | B13: ='ID+C credit category view'!B23>0 -> FALSE | C13: ='ID+C credit category view'!C23>0 -> FALSE | D13: WE Credit | E13: ='ID+C credit category view'!E23 -> WEc2 | F13: ='ID+C credit category view'!F23 -> Enhanced Water Efficiency | G13: ='ID+C credit category view'!K23 | I13: ='ID+C credit category view'!A44>0 -> FALSE | J13: ='ID+C credit category view'!B44>0 -> FALSE | K13: ='ID+C credit category view'!C44>0 -> FALSE | L13: MR Credit | M13: ='ID+C credit category view'!E44 -> MRc4 | N13: ='ID+C credit category view'!F44 -> Building Product Selection and Procurement | O13: ='ID+C credit category view'!K44 | Q13: ='ID+C credit category view'!A44>0 -> FALSE | R13: ='ID+C credit category view'!B44>0 -> FALSE | S13: ='ID+C credit category view'!C44>0 -> FALSE | T13: MR Credit | U13: ='ID+C credit category view'!E44 -> MRc4 | V13: ='ID+C credit category view'!F44 -> Building Product Selection and Procurement | W13: ='ID+C credit category view'!K44
A14: ='ID+C credit category view'!A26 -> FALSE | B14: ='ID+C credit category view'!B26 -> FALSE | C14: ='ID+C credit category view'!C26 -> FALSE | D14: EA Prereq | E14: ='ID+C credit category view'!E26 -> EAp1 | F14: ='ID+C credit category view'!F26 -> Estimated Energy Use and Operational Carbon Projection | I14: ='ID+C credit category view'!A48 -> FALSE | J14: ='ID+C credit category view'!B48 -> FALSE | K14: ='ID+C credit category view'!C48 -> FALSE | L14: EQ Prereq | M14: ='ID+C credit category view'!E48 -> EQp1 | N14: ='ID+C credit category view'!F48 -> Construction Management | Q14: ='ID+C credit category view'!A45>0 -> FALSE | R14: ='ID+C credit category view'!B45>0 -> FALSE | S14: ='ID+C credit category view'!C45>0 -> FALSE | T14: MR Credit | U14: ='ID+C credit category view'!E45 -> MRc5 | V14: ='ID+C credit category view'!F45 -> Construction and Demolition Waste Diversion | W14: ='ID+C credit category view'!K45
A15: ='ID+C credit category view'!A27 -> FALSE | B15: ='ID+C credit category view'!B27 -> FALSE | C15: ='ID+C credit category view'!C27 -> FALSE | D15: EA Prereq | E15: ='ID+C credit category view'!E27 -> EAp2 | F15: ='ID+C credit category view'!F27 -> Minimum Energy Efficiency | I15: ='ID+C credit category view'!A49 -> FALSE | J15: ='ID+C credit category view'!B49 -> FALSE | K15: ='ID+C credit category view'!C49 -> FALSE | L15: EQ Prereq | M15: ='ID+C credit category view'!E49 -> EQp2 | N15: ='ID+C credit category view'!F49 -> Fundamental Air Quality | Q15: ='ID+C credit category view'!A50 -> FALSE | R15: ='ID+C credit category view'!B50 -> FALSE | S15: ='ID+C credit category view'!C50 -> FALSE | T15: EQ Prereq | U15: ='ID+C credit category view'!E50 -> EQp3 | V15: ='ID+C credit category view'!F50 -> No Smoking
A16: ='ID+C credit category view'!A28 -> FALSE | B16: ='ID+C credit category view'!B28 -> FALSE | C16: ='ID+C credit category view'!C28 -> FALSE | D16: EA Prereq | E16: ='ID+C credit category view'!E28 -> EAp3 | F16: ='ID+C credit category view'!F28 -> Fundamental Commissioning | I16: ='ID+C credit category view'!A50 -> FALSE | J16: ='ID+C credit category view'!B50 -> FALSE | K16: ='ID+C credit category view'!C50 -> FALSE | L16: EQ Prereq | M16: ='ID+C credit category view'!E50 -> EQp3 | N16: ='ID+C credit category view'!F50 -> No Smoking
A17: ='ID+C credit category view'!A29 -> FALSE | B17: ='ID+C credit category view'!B29 -> FALSE | C17: ='ID+C credit category view'!C29 -> FALSE | D17: EA Prereq | E17: ='ID+C credit category view'!E29 -> EAp4 | F17: ='ID+C credit category view'!F29 -> Energy Metering and Reporting | I17: ='ID+C credit category view'!A51>0 -> FALSE | J17: ='ID+C credit category view'!B51>0 -> FALSE | K17: ='ID+C credit category view'!C51>0 -> FALSE | L17: EQ Credit | M17: ='ID+C credit category view'!E51 -> EQc1 | N17: ='ID+C credit category view'!F51 -> Enhanced Air Quality | O17: ='ID+C credit category view'!K51
A18: ='ID+C credit category view'!A30 -> FALSE | B18: ='ID+C credit category view'!B30 -> FALSE | C18: ='ID+C credit category view'!C30 -> FALSE | D18: EA Prereq | E18: ='ID+C credit category view'!E30 -> EAp5 | F18: ='ID+C credit category view'!F30 -> Fundamental Refrigerant Management | I18: ='ID+C credit category view'!A52>0 -> FALSE | J18: ='ID+C credit category view'!B52>0 -> FALSE | K18: ='ID+C credit category view'!C52>0 -> FALSE | L18: EQ Credit | M18: ='ID+C credit category view'!E52 -> EQc2 | N18: ='ID+C credit category view'!F52 -> Occupant Experience | O18: ='ID+C credit category view'!K52
A19: ='ID+C credit category view'!A31>0 -> FALSE | B19: ='ID+C credit category view'!B31>0 -> FALSE | C19: ='ID+C credit category view'!C31>0 -> FALSE | D19: EA Credit | E19: ='ID+C credit category view'!E31 -> EAc1 | F19: ='ID+C credit category view'!F31 -> Electrification | G19: ='ID+C credit category view'!K31 | I19: ='ID+C credit category view'!A53>0 -> FALSE | J19: ='ID+C credit category view'!B53>0 -> FALSE | K19: ='ID+C credit category view'!C53>0 -> FALSE | L19: EQ Credit | M19: ='ID+C credit category view'!E53 -> EQc3 | N19: ='ID+C credit category view'!F53 -> Accessibility and Inclusion | O19: ='ID+C credit category view'!K53
A20: ='ID+C credit category view'!A32>0 -> FALSE | B20: ='ID+C credit category view'!B32>0 -> FALSE | C20: ='ID+C credit category view'!C32>0 -> FALSE | D20: EA Credit | E20: ='ID+C credit category view'!E32 -> EAc2 | F20: ='ID+C credit category view'!F32 -> Enhanced Energy Efficiency | G20: ='ID+C credit category view'!K32 | I20: ='ID+C credit category view'!A54>0 -> FALSE | J20: ='ID+C credit category view'!B54>0 -> FALSE | K20: ='ID+C credit category view'!C54>0 -> FALSE | L20: EQ Credit | M20: ='ID+C credit category view'!E54 -> EQc4 | N20: ='ID+C credit category view'!F54 -> Resilient Spaces | O20: ='ID+C credit category view'!K54
A21: ='ID+C credit category view'!A33>0 -> FALSE | B21: ='ID+C credit category view'!B33>0 -> FALSE | C21: ='ID+C credit category view'!C33>0 -> FALSE | D21: EA Credit | E21: ='ID+C credit category view'!E33 -> EAc3 | F21: ='ID+C credit category view'!F33 -> Renewable Energy | G21: ='ID+C credit category view'!K33 | I21: ='ID+C credit category view'!A55>0 -> FALSE | J21: ='ID+C credit category view'!B55>0 -> FALSE | K21: ='ID+C credit category view'!C55>0 -> FALSE | L21: EQ Credit | M21: ='ID+C credit category view'!E55 -> EQc5 | N21: ='ID+C credit category view'!F55 -> Air Quality Testing and Monitoring | O21: ='ID+C credit category view'!K55
A22: ='ID+C credit category view'!A34>0 -> FALSE | B22: ='ID+C credit category view'!B34>0 -> FALSE | C22: ='ID+C credit category view'!C34>0 -> FALSE | D22: EA Credit | E22: ='ID+C credit category view'!E34 -> EAc4 | F22: ='ID+C credit category view'!F34 -> Enhanced Commissioning | G22: ='ID+C credit category view'!K34
A23: ='ID+C credit category view'!A35>0 -> FALSE | B23: ='ID+C credit category view'!B35>0 -> FALSE | C23: ='ID+C credit category view'!C35>0 -> FALSE | D23: EA Credit | E23: ='ID+C credit category view'!E35 -> EAc5 | F23: ='ID+C credit category view'!F35 -> Grid Interactive | G23: ='ID+C credit category view'!K35
A24: ='ID+C credit category view'!A36>0 -> FALSE | B24: ='ID+C credit category view'!B36>0 -> FALSE | C24: ='ID+C credit category view'!C36>0 -> FALSE | D24: EA Credit | E24: ='ID+C credit category view'!E36 -> EAc6 | F24: ='ID+C credit category view'!F36 -> Enhanced Refrigerant Management | G24: ='ID+C credit category view'!K36
A25: ='ID+C credit category view'!A39 -> FALSE | B25: ='ID+C credit category view'!B39 -> FALSE | C25: ='ID+C credit category view'!C39 -> FALSE | D25: MR Prereq | E25: ='ID+C credit category view'!E39 -> MRp1 | F25: ='ID+C credit category view'!F39 -> Planning for Zero Waste Operations
A26: ='ID+C credit category view'!A40 -> FALSE | B26: ='ID+C credit category view'!B40 -> FALSE | C26: ='ID+C credit category view'!C40 -> FALSE | D26: MR Prereq | E26: ='ID+C credit category view'!E40 -> MRp2 | F26: ='ID+C credit category view'!F40 -> Quantify and Assess Embodied Carbon
A27: ='ID+C credit category view'!A41>0 -> FALSE | B27: ='ID+C credit category view'!B41>0 -> FALSE | C27: ='ID+C credit category view'!C41>0 -> FALSE | D27: MR Credit | E27: ='ID+C credit category view'!E41 -> MRc1 | F27: ='ID+C credit category view'!F41 -> Interior Materials Reuse | G27: ='ID+C credit category view'!K41
A28: ='ID+C credit category view'!A42>0 -> FALSE | B28: ='ID+C credit category view'!B42>0 -> FALSE | C28: ='ID+C credit category view'!C42>0 -> FALSE | D28: MR Credit | E28: ='ID+C credit category view'!E42 -> MRc2 | F28: ='ID+C credit category view'!F42 -> Reduce Embodied Carbon | G28: ='ID+C credit category view'!K42
A29: ='ID+C credit category view'!A44>0 -> FALSE | B29: ='ID+C credit category view'!B44>0 -> FALSE | C29: ='ID+C credit category view'!C44>0 -> FALSE | D29: MR Credit | E29: ='ID+C credit category view'!E44 -> MRc4 | F29: ='ID+C credit category view'!F44 -> Building Product Selection and Procurement | G29: ='ID+C credit category view'!K44
A30: ='ID+C credit category view'!A45>0 -> FALSE | B30: ='ID+C credit category view'!B45>0 -> FALSE | C30: ='ID+C credit category view'!C45>0 -> FALSE | D30: MR Credit | E30: ='ID+C credit category view'!E45 -> MRc5 | F30: ='ID+C credit category view'!F45 -> Construction and Demolition Waste Diversion | G30: ='ID+C credit category view'!K45

Sheet Analytics
A2: LEED v5 for Interior Design and Construction: Commercial Interiors
A3: Project scorecard analytics

Sheet Background
A1: Data Validation | I1: Yes | J1: ='ID+C credit category view'!M2 -> 0
A2: Yes | I2: Maybe | J2: ='ID+C credit category view'!M3 -> 0
A3: Maybe | I3: No | J3: ='ID+C credit category view'!M4 -> 0
A4: No | I4: Blank | J4: =J12-J3-J2-J1 -> 110 | Q4: Decarbonization
I5: Related Charts | Q5: Yes | R5: Maybe | S5: No | T5: Blank
I6: Total Anticipated Points Distribution | Q6: =COUNTIF('ID+C impact area view '!A6:A30, "TRUE") -> 0 | R6: =COUNTIF('ID+C impact area view '!B6:B30, "TRUE") -> 0 | S6: =COUNTIF('ID+C impact area view '!C6:C30, "TRUE") -> 0 | T6: =COUNTA('ID+C impact area view '!E6:E30)-S6-R6-Q6 -> 25
I7: Total Anticipated Points Distribution | Q7: Quality of Life
Q8: Yes | R8: Maybe | S8: No | T8: Blank
I9: Total Anticipated Points | J9: ='ID+C credit category view'!M6 -> 0 | K9: points | Q9: =COUNTIF('ID+C impact area view '!I6:I21, "TRUE") -> 0 | R9: =COUNTIF('ID+C impact area view '!J6:J21, "TRUE") -> 0 | S9: =COUNTIF('ID+C impact area view '!K6:K21, "TRUE") -> 0 | T9: =COUNTA('ID+C impact area view '!M3:M21)-S9-R9-Q9 -> 16
I10: Certified Project | J10: 40 | K10: points | Q10: Ecological Conservation and Restoration
I11: Platinum Project | J11: 80 | K11: points | Q11: Yes | R11: Maybe | S11: No | T11: Blank
I12: Total Possible Points | J12: ='ID+C credit category view'!M7 -> 110 | K12: points | Q12: =COUNTIF('ID+C impact area view '!Q6:Q21, "TRUE") -> 0 | R12: =COUNTIF('ID+C impact area view '!R6:R21, "TRUE") -> 0 | S12: =COUNTIF('ID+C impact area view '!S6:S21, "TRUE") -> 0 | T12: =COUNTA('ID+C impact area view '!M6:M21)-S12-R12-Q12 -> 16
I13: Related Charts
I14: Total Anticipated Points versus LEED Certification Levels | P14: Anticipated Decarbonization Credits
E15: Total Possible Points | F15: Total Anticipated Points | P15: Anticipated Quality of Life Credits
P16: Anticipated Ecological Conservation and Restoration Credits
A18: ='ID+C credit category view'!E9 -> Integrative Process, Planning and Assessments (IP) | E18: ='ID+C credit category view'!I9 -> 1 | F18: ='ID+C credit category view'!J9 -> 0
A19: ='ID+C credit category view'!E15 -> Location and Transportation (LT) | E19: ='ID+C credit category view'!I15 -> 14 | F19: ='ID+C credit category view'!J15 -> 0
A20: ='ID+C credit category view'!E20 -> Water Efficiency (WE) | E20: ='ID+C credit category view'!I20 -> 10 | F20: ='ID+C credit category view'!J20 -> 0
A21: ='ID+C credit category view'!E25 -> Energy and Atmosphere (EA) | E21: ='ID+C credit category view'!I25 -> 31 | F21: ='ID+C credit category view'!J25 -> 0
A22: ='ID+C credit category view'!E38 -> Materials and Resources (MR) | E22: ='ID+C credit category view'!I38 -> 26 | F22: ='ID+C credit category view'!J38 -> 0
A23: ='ID+C credit category view'!E47 -> Indoor Environmental Quality (EQ) | E23: ='ID+C credit category view'!I47 -> 18 | F23: ='ID+C credit category view'!J47 -> 0
A24: ='ID+C credit category view'!E57 -> Project Priorities (PR) | E24: ='ID+C credit category view'!I57 -> 10 | F24: ='ID+C credit category view'!J57 -> 0
A25: Related Charts
A26: Total Possible Points by Credit Category
A27: Total Anticipated Points by Credit Category
